<!-- spawn_empty.py好像处理不了这种xml格式的标签 -->
<!-- ?xml version="1.0" encoding="utf-8"? -->
<!-- This URDF was automatically created by SolidWorks to URDF Exporter! Originally created by Stephen Brawner (brawner@gmail.com) 
     Commit Version: 1.6.0-4-g7f85cfe  Build Version: 1.6.7995.38578
     For more information, please see http://wiki.ros.org/sw_urdf_exporter -->
<robot
  name="four_omniwheel_robot">
  <link
    name="base_link">
    <inertial>
      <origin
        xyz="-0.065349 -0.038745 -1.6094E-08"
        rpy="0 0 0" />
      <mass
        value="93.59" />
      <inertia
        ixx="3.1515"
        ixy="-5.5081E-08"
        ixz="-1.0742E-07"
        iyy="3.5103"
        iyz="-1.9077E-07"
        izz="3.1515" />
    </inertial>
    <visual>
      <origin
        xyz="0 0 0"
        rpy="0 0 0" />
      <geometry>
        <mesh
          filename="package://four_omniwheel_robot/meshes/base_link.STL" />
      </geometry>
      <material
        name="">
        <color
          rgba="1 1 1 1" />
      </material>
    </visual>
    <collision>
      <origin
        xyz="0 0 0"
        rpy="0 0 0" />
      <geometry>
        <mesh
          filename="package://four_omniwheel_robot/meshes/base_link.STL" />
      </geometry>
    </collision>
  </link>
  <link
    name="omniwheel1_Link">
    <inertial>
      <origin
        xyz="5.5106E-07 -0.024566 1.5467E-06"
        rpy="0 0 0" />
      <mass
        value="0.43122" />
      <inertia
        ixx="0.0001743"
        ixy="2.1816E-22"
        ixz="-2.676E-09"
        iyy="0.00033869"
        iyz="-5.7776E-19"
        izz="0.00017429" />
    </inertial>
    <visual>
      <origin
        xyz="0 0 0"
        rpy="0 0 0" />
      <geometry>
        <mesh
          filename="package://four_omniwheel_robot/meshes/omniwheel1_Link.STL" />
      </geometry>
      <material
        name="">
        <color
          rgba="0.75294 0.75294 0.75294 1" />
      </material>
    </visual>
    <collision>
      <origin
        xyz="0 0 0"
        rpy="0 0 0" />
      <geometry>
        <mesh
          filename="package://four_omniwheel_robot/meshes/omniwheel1_Link.STL" />
      </geometry>
    </collision>
  </link>
  <joint
    name="omniwheel1_joint"
    type="continuous">
    <origin
      xyz="-0.356282834449602 0 -0.199067987151237"
      rpy="1.5707963267949 1.5707963267949 0" />
    <parent
      link="base_link" />
    <child
      link="omniwheel1_Link" />
    <axis
      xyz="0 1 0" />
  </joint>
  <link
    name="omniwheel2_Link">
    <inertial>
      <origin
        xyz="5.5106E-07 -0.0085 1.5467E-06"
        rpy="0 0 0" />
      <mass
        value="0.43122" />
      <inertia
        ixx="0.0001743"
        ixy="8.2234E-21"
        ixz="-2.676E-09"
        iyy="0.00033869"
        iyz="-1.2018E-20"
        izz="0.00017429" />
    </inertial>
    <visual>
      <origin
        xyz="0 0 0"
        rpy="0 0 0" />
      <geometry>
        <mesh
          filename="package://four_omniwheel_robot/meshes/omniwheel2_Link.STL" />
      </geometry>
      <material
        name="">
        <color
          rgba="0.75294 0.75294 0.75294 1" />
      </material>
    </visual>
    <collision>
      <origin
        xyz="0 0 0"
        rpy="0 0 0" />
      <geometry>
        <mesh
          filename="package://four_omniwheel_robot/meshes/omniwheel2_Link.STL" />
      </geometry>
    </collision>
  </link>
  <joint
    name="omniwheel2_joint"
    type="fixed">
    <origin
      xyz="-0.065349042145596 -0.307 -0.199067987151237"
      rpy="0 1.5707963267949 0" />
    <parent
      link="base_link" />
    <child
      link="omniwheel2_Link" />
    <axis
      xyz="0 0 0" />
  </joint>
  <link
    name="omniwheel3_Link">
    <inertial>
      <origin
        xyz="5.5106E-07 -0.0085 1.5467E-06"
        rpy="0 0 0" />
      <mass
        value="0.43122" />
      <inertia
        ixx="0.0001743"
        ixy="2.0836E-21"
        ixz="-2.676E-09"
        iyy="0.00033869"
        iyz="-2.4819E-20"
        izz="0.00017429" />
    </inertial>
    <visual>
      <origin
        xyz="0 0 0"
        rpy="0 0 0" />
      <geometry>
        <mesh
          filename="package://four_omniwheel_robot/meshes/omniwheel3_Link.STL" />
      </geometry>
      <material
        name="">
        <color
          rgba="0.75294 0.75294 0.75294 1" />
      </material>
    </visual>
    <collision>
      <origin
        xyz="0 0 0"
        rpy="0 0 0" />
      <geometry>
        <mesh
          filename="package://four_omniwheel_robot/meshes/omniwheel3_Link.STL" />
      </geometry>
    </collision>
  </link>
  <joint
    name="omniwheel3_joint"
    type="fixed">
    <origin
      xyz="0.241650957854406 0 -0.199067987151237"
      rpy="1.57079632679489 1.5707963267949 0" />
    <parent
      link="base_link" />
    <child
      link="omniwheel3_Link" />
    <axis
      xyz="0 0 0" />
  </joint>
  <link
    name="omniwheel4_Link">
    <inertial>
      <origin
        xyz="5.51055494374397E-07 -0.00849999999999967 1.54673931779259E-06"
        rpy="0 0 0" />
      <mass
        value="0.431215675623418" />
      <inertia
        ixx="0.000174298438940504"
        ixy="1.83312695076309E-22"
        ixz="-2.67597476170389E-09"
        iyy="0.000338687971226704"
        iyz="-2.99150553199584E-22"
        izz="0.000174292269080151" />
    </inertial>
    <visual>
      <origin
        xyz="0 0 0"
        rpy="0 0 0" />
      <geometry>
        <mesh
          filename="package://four_omniwheel_robot/meshes/omniwheel4_Link.STL" />
      </geometry>
      <material
        name="">
        <color
          rgba="0.752941176470588 0.752941176470588 0.752941176470588 1" />
      </material>
    </visual>
    <collision>
      <origin
        xyz="0 0 0"
        rpy="0 0 0" />
      <geometry>
        <mesh
          filename="package://four_omniwheel_robot/meshes/omniwheel4_Link.STL" />
      </geometry>
    </collision>
  </link>
  <joint
    name="omniwheel4_joint"
    type="fixed">
    <origin
      xyz="-0.0653490421455938 0.307 -0.199067987151237"
      rpy="3.14159265358979 1.5707963267949 0" />
    <parent
      link="base_link" />
    <child
      link="omniwheel4_Link" />
    <axis
      xyz="0 0 0" />
  </joint>
  <link
    name="mid360laser_link">
    <inertial>
      <origin
        xyz="0.00019958 0.0038854 -0.033431"
        rpy="0 0 0" />
      <mass
        value="0.14189" />
      <inertia
        ixx="4.1798E-05"
        ixy="3.0533E-07"
        ixz="-5.7194E-09"
        iyy="6.8799E-05"
        iyz="-4.3975E-10"
        izz="4.5077E-05" />
    </inertial>
    <visual>
      <origin
        xyz="0 0 0"
        rpy="0 0 0" />
      <geometry>
        <mesh
          filename="package://four_omniwheel_robot/meshes/mid360laser_link.STL" />
      </geometry>
      <material
        name="">
        <color
          rgba="0.75294 0.75294 0.75294 1" />
      </material>
    </visual>
    <collision>
      <origin
        xyz="0 0 0"
        rpy="0 0 0" />
      <geometry>
        <mesh
          filename="package://four_omniwheel_robot/meshes/mid360laser_link.STL" />
      </geometry>
    </collision>
  </link>
  <joint
    name="mid360laser_joint"
    type="fixed">
    <origin
      xyz="-0.25587 0 0.099658"
      rpy="-1.5708 0 -1.5708" />
    <parent
      link="base_link" />
    <child
      link="mid360laser_link" />
    <axis
      xyz="0 0 0" />
  </joint>
  <link
    name="controller_Link">
    <inertial>
      <origin
        xyz="0 0 0"
        rpy="0 0 0" />
      <mass
        value="0" />
      <inertia
        ixx="0"
        ixy="0"
        ixz="0"
        iyy="0"
        iyz="0"
        izz="0" />
    </inertial>
    <visual>
      <origin
        xyz="0 0 0"
        rpy="0 0 0" />
      <geometry>
        <mesh
          filename="package://four_omniwheel_robot/meshes/controller_Link.STL" />
      </geometry>
      <material
        name="">
        <color
          rgba="1 1 1 1" />
      </material>
    </visual>
    <collision>
      <origin
        xyz="0 0 0"
        rpy="0 0 0" />
      <geometry>
        <mesh
          filename="package://four_omniwheel_robot/meshes/controller_Link.STL" />
      </geometry>
    </collision>
  </link>
  <joint
    name="controller_joint"
    type="fixed">
    <origin
      xyz="-0.065349 0 -0.22626"
      rpy="1.5708 0 0" />
    <parent
      link="base_link" />
    <child
      link="controller_Link" />
    <axis
      xyz="0 0 0" />
  </joint>
</robot>
