<?xml version='1.0'?>
<sdf version='1.7'>
  <model name='four_omniwheel_robot'>
    <link name='base_link'>
      <inertial>
        <pose>-0.064329 -0.03816 -0.002567 0 -0 0</pose>
        <mass>95.0255</mass>
        <inertia>
          <ixx>3.29214</ixx>
          <ixy>-0.0037051</ixy>
          <ixz>0.0284183</ixz>
          <iyy>3.60857</iyy>
          <iyz>0.00931105</iyz>
          <izz>3.2855</izz>
        </inertia>
      </inertial>
      <collision name='base_link_collision'>
        <pose>0 0 0 0 -0 0</pose>
        <geometry>
          <mesh>
            <scale>1 1 1</scale>
            <uri>model://four_omniwheel_robot/meshes/base_link.STL</uri>
          </mesh>
        </geometry>
      </collision>
      <collision name='base_link_fixed_joint_lump__controller_Link_collision_1'>
        <pose>-0.065349 0 -0.22626 1.5708 -0 0</pose>
        <geometry>
          <mesh>
            <scale>1 1 1</scale>
            <uri>model://four_omniwheel_robot/meshes/controller_Link.STL</uri>
          </mesh>
        </geometry>
      </collision>
      <collision name='base_link_fixed_joint_lump__mid360laser_link_collision_2'>
        <pose>-0.25587 0 0.099658 -1.5708 -0 -1.5708</pose>
        <geometry>
          <mesh>
            <scale>1 1 1</scale>
            <uri>model://four_omniwheel_robot/meshes/mid360laser_link.STL</uri>
          </mesh>
        </geometry>
      </collision>
      <collision name='base_link_fixed_joint_lump__omniwheel2_Link_collision_3'>
        <pose>-0.065349 -0.307 -0.199068 0 1.5708 0</pose>
        <geometry>
          <mesh>
            <scale>1 1 1</scale>
            <uri>model://four_omniwheel_robot/meshes/omniwheel2_Link.STL</uri>
          </mesh>
        </geometry>
      </collision>
      <collision name='base_link_fixed_joint_lump__omniwheel3_Link_collision_4'>
        <pose>0.241651 0 -0.199068 1.5708 1.5708 0</pose>
        <geometry>
          <mesh>
            <scale>1 1 1</scale>
            <uri>model://four_omniwheel_robot/meshes/omniwheel3_Link.STL</uri>
          </mesh>
        </geometry>
      </collision>
      <collision name='base_link_fixed_joint_lump__omniwheel4_Link_collision_5'>
        <pose>-0.065349 0.307 -0.199068 3.14159 1.5708 0</pose>
        <geometry>
          <mesh>
            <scale>1 1 1</scale>
            <uri>model://four_omniwheel_robot/meshes/omniwheel4_Link.STL</uri>
          </mesh>
        </geometry>
      </collision>
      <visual name='base_link_visual'>
        <pose>0 0 0 0 -0 0</pose>
        <geometry>
          <mesh>
            <scale>1 1 1</scale>
            <uri>model://four_omniwheel_robot/meshes/base_link.STL</uri>
          </mesh>
        </geometry>
      </visual>
      <visual name='base_link_fixed_joint_lump__controller_Link_visual_1'>
        <pose>-0.065349 0 -0.22626 1.5708 -0 0</pose>
        <geometry>
          <mesh>
            <scale>1 1 1</scale>
            <uri>model://four_omniwheel_robot/meshes/controller_Link.STL</uri>
          </mesh>
        </geometry>
      </visual>
      <visual name='base_link_fixed_joint_lump__mid360laser_link_visual_2'>
        <pose>-0.25587 0 0.099658 -1.5708 -0 -1.5708</pose>
        <geometry>
          <mesh>
            <scale>1 1 1</scale>
            <uri>model://four_omniwheel_robot/meshes/mid360laser_link.STL</uri>
          </mesh>
        </geometry>
      </visual>
      <visual name='base_link_fixed_joint_lump__omniwheel2_Link_visual_3'>
        <pose>-0.065349 -0.307 -0.199068 0 1.5708 0</pose>
        <geometry>
          <mesh>
            <scale>1 1 1</scale>
            <uri>model://four_omniwheel_robot/meshes/omniwheel2_Link.STL</uri>
          </mesh>
        </geometry>
      </visual>
      <visual name='base_link_fixed_joint_lump__omniwheel3_Link_visual_4'>
        <pose>0.241651 0 -0.199068 1.5708 1.5708 0</pose>
        <geometry>
          <mesh>
            <scale>1 1 1</scale>
            <uri>model://four_omniwheel_robot/meshes/omniwheel3_Link.STL</uri>
          </mesh>
        </geometry>
      </visual>
      <visual name='base_link_fixed_joint_lump__omniwheel4_Link_visual_5'>
        <pose>-0.065349 0.307 -0.199068 3.14159 1.5708 0</pose>
        <geometry>
          <mesh>
            <scale>1 1 1</scale>
            <uri>model://four_omniwheel_robot/meshes/omniwheel4_Link.STL</uri>
          </mesh>
        </geometry>
      </visual>
    </link>
    <joint name='omniwheel1_joint' type='revolute'>
      <pose relative_to='base_link'>-0.356283 0 -0.199068 1.5708 1.5708 0</pose>
      <parent>base_link</parent>
      <child>omniwheel1_Link</child>
      <axis>
        <xyz>0 1 0</xyz>
        <limit>
          <lower>-1e+16</lower>
          <upper>1e+16</upper>
        </limit>
        <dynamics>
          <spring_reference>0</spring_reference>
          <spring_stiffness>0</spring_stiffness>
        </dynamics>
      </axis>
    </joint>
    <link name='omniwheel1_Link'>
      <pose relative_to='omniwheel1_joint'>0 0 0 0 -0 0</pose>
      <inertial>
        <pose>1e-06 -0.024566 2e-06 0 -0 0</pose>
        <mass>0.43122</mass>
        <inertia>
          <ixx>0.0001743</ixx>
          <ixy>2.1816e-22</ixy>
          <ixz>-2.676e-09</ixz>
          <iyy>0.00033869</iyy>
          <iyz>-5.7776e-19</iyz>
          <izz>0.00017429</izz>
        </inertia>
      </inertial>
      <collision name='omniwheel1_Link_collision'>
        <pose>0 0 0 0 -0 0</pose>
        <geometry>
          <mesh>
            <scale>1 1 1</scale>
            <uri>model://four_omniwheel_robot/meshes/omniwheel1_Link.STL</uri>
          </mesh>
        </geometry>
      </collision>
      <visual name='omniwheel1_Link_visual'>
        <pose>0 0 0 0 -0 0</pose>
        <geometry>
          <mesh>
            <scale>1 1 1</scale>
            <uri>model://four_omniwheel_robot/meshes/omniwheel1_Link.STL</uri>
          </mesh>
        </geometry>
      </visual>
    </link>
  </model>
</sdf>