<?xml version="1.0"?>
<robot name = "sim_robot" xmlns:xacro="https://ros.org/wiki/xacro">
    <xacro:property name="base_width" value="0.60"/>
    <xacro:property name="base_lenth" value="0.60"/>
    <xacro:property name="base_height" value="0.55"/>
    <xacro:property name="PI" value="3.1415926"/>
    <xacro:property name="wheel_radius" value="0.10"/>
    <xacro:property name="wheel_width" value="0.04"/>
    <xacro:property name="wheel_ygap" value="0.025"/>
    <xacro:property name="wheel_zoff" value="0.05"/>
    <xacro:property name="wheel_xoff" value="0.12"/>

    <xacro:property name="caster_xoff" value="0.14"/>
    <xacro:property name="caster_yoff" value="0.14"/>
    <xacro:property name="caster_zoff" value="0.05"/>
    <xacro:property name="caster_radius" value="0.02"/>

  <link name="base_link">
    <visual>
      <geometry>
        <cylinder length="0.1" radius="0.1"/>
      </geometry>
      <origin rpy="0 0 0" xyz="0 0 0"/>
      <material name="black">
        <color rgba="0 0 0 1"/>
      </material>
    </visual>
    <collision>
      <geometry>
        <cylinder length="0.1" radius="0.1"/>
      </geometry>
    </collision>
    <inertial>
      <origin rpy="0 0 0" xyz="0 0 0"/>
      <mass value="1"/>
      <inertia ixx="0.1" ixy="0" ixz="0" iyy="0.1" iyz="0" izz="0.1"/>
    </inertial>
  </link>
  <link name="base_footprint"/>
    <joint name="base_footprint_joint" type="fixed">
        <parent link="base_footprint"/>
        <child link="base_link"/>
        <origin xyz="0 0 0" rpy="0 0 0"/>
    </joint>
    
    <xacro:macro name="wheel" params="name prefix x_reflect y_reflect x y z">
    <link name="${prefix}_link">
        <visual>
            <geometry>
                <cylinder length="${wheel_width}" radius="${wheel_radius}"/>
            </geometry>
            <origin rpy="0 0 0" xyz="${x} ${y} ${z}"/>
            <material name="Gray">
                <color rgba="0.5 0.5 0.5 1.0"/>
            </material>
        </visual>
        <collision>
            <geometry>
                <cylinder length="${wheel_width}" radius="${wheel_radius}"/>
            </geometry>
        </collision>
        <inertial>
            <origin rpy="0 0 0" xyz="${x} ${y} ${z}"/>
            <mass value="1"/>
            <inertia ixx="0.1" ixy="0" ixz="0" iyy="0.1" iyz="0" izz="0.1"/>
        </inertial>
    </link>
    <joint name="${prefix}_joint" type="continuous">
        <parent link="base_link"/>
        <child link="${prefix}_link"/>
        <origin xyz="${x_reflect*wheel_xoff} ${y_reflect*(base_width/2+wheel_ygap)} ${-wheel_zoff} " rpy="0 0 0"/>
        <axis xyz="0 1 0"/>    
    </joint>
    </xacro:macro>
    <xacro:wheel name="wheel_1" prefix="wheel_1" x_reflect="1" y_reflect="1" x="0" y="0" z="0"/>
    <xacro:wheel name="wheel_2" prefix="wheel_2" x_reflect="1" y_reflect="-1" x="0" y="0" z="0"/>
    <xacro:wheel name="wheel_3" prefix="wheel_3" x_reflect="-1" y_reflect="1" x="0" y="0" z="0"/>
    <xacro:wheel name="wheel_4" prefix="wheel_4" x_reflect="-1" y_reflect="-1" x="0" y="0" z="0"/>
    <xacro:wheel name="caster_1" prefix="caster_1" x_reflect="1" y_reflect="1" x="0" y="0" z="0"/>
    <xacro:wheel name="caster_2" prefix="caster_2" x_reflect="1" y_reflect="-1" x="0" y="0" z="0"/>
    <xacro:wheel name="caster_3" prefix="caster_3" x_reflect="-1" y_reflect="1" x="0" y="0" z="0"/>
    <xacro:wheel name="caster_4" prefix="caster_4" x_reflect="-1" y_reflect="-1" x="0" y="0" z="0"/>
</robot>
